<sdf version='1.4'>
  <world name='default'>
    <model name='ground_plane'>
      <static>1</static>
      <link name='link'>
        <collision name='collision'>
          <geometry>
            <plane>
              <normal>0 0 1</normal>
              <size>100 100</size>
            </plane>
          </geometry>
          <surface>
            <friction>
              <ode>
                <mu>100</mu>
                <mu2>50</mu2>
              </ode>
            </friction>
            <bounce/>
            <contact>
              <ode/>
            </contact>
          </surface>
          <max_contacts>10</max_contacts>
        </collision>
        <visual name='visual'>
          <cast_shadows>0</cast_shadows>
          <geometry>
            <plane>
              <normal>0 0 1</normal>
              <size>100 100</size>
            </plane>
          </geometry>
          <material>
            <script>
              <uri>file://media/materials/scripts/gazebo.material</uri>
              <name>Gazebo/Grey</name>
            </script>
          </material>
        </visual>
        <velocity_decay>
          <linear>0</linear>
          <angular>0</angular>
        </velocity_decay>
        <self_collide>0</self_collide>
        <kinematic>0</kinematic>
        <gravity>1</gravity>
      </link>
    </model>
    <light name='sun' type='directional'>
      <cast_shadows>1</cast_shadows>
      <pose>0 0 10 0 -0 0</pose>
      <diffuse>0.8 0.8 0.8 1</diffuse>
      <specular>0.2 0.2 0.2 1</specular>
      <attenuation>
        <range>1000</range>
        <constant>0.9</constant>
        <linear>0.01</linear>
        <quadratic>0.001</quadratic>
      </attenuation>
      <direction>-0.5 0.1 -0.9</direction>
    </light>
    <gui fullscreen='0'>
      <camera name='user_camera'>
        <pose>46.1956 -34.9392 25.0368 0 0.645796 2.13312</pose>
        <view_controller>orbit</view_controller>
      </camera>
    </gui>
    <physics type='ode'>
      <gravity>0 0 -9.81</gravity>
      <max_step_size>0.01</max_step_size>
      <real_time_factor>1</real_time_factor>
      <real_time_update_rate>100</real_time_update_rate>
      <ode>
        <solver>
          <type>quick</type>
          <iters>5000</iters>
          <sor>1.3</sor>
        </solver>
        <constraints>
          <cfm>0</cfm>
          <erp>0.1</erp>
          <contact_max_correcting_vel>100</contact_max_correcting_vel>
          <contact_surface_layer>0.001</contact_surface_layer>
        </constraints>
      </ode>
    </physics>
    <scene>
      <ambient>0.4 0.4 0.4 1</ambient>
      <background>0.7 0.7 0.7 1</background>
      <shadows>1</shadows>
    </scene>
    <spherical_coordinates>
      <surface_model>EARTH_WGS84</surface_model>
      <latitude_deg>0</latitude_deg>
      <longitude_deg>0</longitude_deg>
      <elevation>0</elevation>
      <heading_deg>0</heading_deg>
    </spherical_coordinates>
    <state world_name='default'>
      <sim_time>1468 666000000</sim_time>
      <real_time>73 251584490</real_time>
      <wall_time>1492979284 417412700</wall_time>
      <model name='House 3'>
        <pose>15 -0.53632 0 0 -0 0</pose>
        <link name='link'>
          <pose>15 -0.53632 0 0 -0 0</pose>
          <velocity>0 0 0 0 -0 0</velocity>
          <acceleration>0 0 0 0 -0 0</acceleration>
          <wrench>0 0 0 0 -0 0</wrench>
        </link>
      </model>
      <model name='catvehicle'>
        <pose>-0.003063 -1.1e-05 -0.315505 -1.65436e-24 0.000943 -9e-06</pose>
        <link name='back_left_wheel_link'>
          <pose>-1.31243 0.765 0.34573 -1.32352e-23 -0.006874 -9e-06</pose>
          <velocity>-8e-05 0 0.000195 0 -0.000224 0</velocity>
          <acceleration>0 0 0 0 -0 0</acceleration>
          <wrench>0 0 0 0 -0 0</wrench>
        </link>
        <link name='back_right_wheel_link'>
          <pose>-1.31245 -0.765 0.34573 -1.32352e-23 -0.006874 -9e-06</pose>
          <velocity>-8e-05 -0 0.000195 0 -0.000224 0</velocity>
          <acceleration>0 0 0 0 -0 0</acceleration>
          <wrench>0 0 0 0 -0 0</wrench>
        </link>
        <link name='base_link'>
          <pose>-0.003063 -1.1e-05 -0.315505 -1.65436e-24 0.000943 -9e-06</pose>
          <velocity>6.8e-05 -0 0.000488 0 -0.000224 0</velocity>
          <acceleration>0 0 0 0 -0 0</acceleration>
          <wrench>0 0 0 0 -0 0</wrench>
        </link>
        <link name='front_left_steering_link'>
          <pose>1.30756 0.655477 0.34326 -1.65436e-24 0.000943 -9e-06</pose>
          <velocity>-7.9e-05 0 0.000782 0 -0.000224 0</velocity>
          <acceleration>0 0 0 0 -0 0</acceleration>
          <wrench>0 0 0 0 -0 0</wrench>
        </link>
        <link name='front_left_wheel_link'>
          <pose>1.30757 0.774977 0.34326 -5.29968e-23 -0.046493 -9e-06</pose>
          <velocity>-7.9e-05 0 0.000782 0 -0.000223 0</velocity>
          <acceleration>0 0 0 0 -0 0</acceleration>
          <wrench>0 0 0 0 -0 0</wrench>
        </link>
        <link name='front_right_steering_link'>
          <pose>1.30755 -0.655523 0.34326 -1.65436e-24 0.000943 -9e-06</pose>
          <velocity>-7.9e-05 0 0.000782 0 -0.000224 0</velocity>
          <acceleration>0 0 0 0 -0 0</acceleration>
          <wrench>0 0 0 0 -0 0</wrench>
        </link>
        <link name='front_right_wheel_link'>
          <pose>1.30755 -0.775023 0.34326 -5.29968e-23 -0.04649 -9e-06</pose>
          <velocity>-7.9e-05 0 0.000782 0 -0.000223 0</velocity>
          <acceleration>0 0 0 0 -0 0</acceleration>
          <wrench>0 0 0 0 -0 0</wrench>
        </link>
      </model>
      <model name='ground_plane'>
        <pose>0 0 0 0 -0 0</pose>
        <link name='link'>
          <pose>0 0 0 0 -0 0</pose>
          <velocity>0 0 0 0 -0 0</velocity>
          <acceleration>0 0 0 0 -0 0</acceleration>
          <wrench>0 0 0 0 -0 0</wrench>
        </link>
      </model>
      <model name='unit_box_1'>
        <pose>8.4453 -3 0.5 0 -0 0</pose>
        <link name='link'>
          <pose>8.4453 -3 0.5 0 -0 0</pose>
          <velocity>0 0 0 0 -0 0</velocity>
          <acceleration>0 0 0 0 -0 0</acceleration>
          <wrench>0 0 0 0 -0 0</wrench>
        </link>
      </model>
      <model name='unit_box_10'>
        <pose>25 3 0.5 -0 -0 -0</pose>
        <link name='link'>
          <pose>25 3 0.5 -0 -0 -0</pose>
          <velocity>0 0 0 0 -0 0</velocity>
          <acceleration>0 0 0 0 -0 0</acceleration>
          <wrench>0 0 0 0 -0 0</wrench>
        </link>
      </model>
      <model name='unit_box_2'>
        <pose>14 -4 0.5 0 -0 0</pose>
        <link name='link'>
          <pose>14 -4 0.5 0 -0 0</pose>
          <velocity>0 0 0 0 -0 0</velocity>
          <acceleration>0 0 0 0 -0 0</acceleration>
          <wrench>0 0 0 0 -0 0</wrench>
        </link>
      </model>
      <model name='unit_box_3'>
        <pose>7 3 0.5 0 -0 0</pose>
        <link name='link'>
          <pose>7 3 0.5 0 -0 0</pose>
          <velocity>0 0 0 0 -0 0</velocity>
          <acceleration>0 0 0 0 -0 0</acceleration>
          <wrench>0 0 0 0 -0 0</wrench>
        </link>
      </model>
      <model name='unit_box_4'>
        <pose>12 2.5989 0.5 -0 -0 -0</pose>
        <link name='link'>
          <pose>12 2.5989 0.5 -0 -0 -0</pose>
          <velocity>0 0 0 0 -0 0</velocity>
          <acceleration>0 0 0 0 -0 0</acceleration>
          <wrench>0 0 0 0 -0 0</wrench>
        </link>
      </model>
      <model name='unit_box_5'>
        <pose>4 3.45674 0.5 0 -0 0</pose>
        <link name='link'>
          <pose>4 3.45674 0.5 0 -0 0</pose>
          <velocity>0 0 0 0 -0 0</velocity>
          <acceleration>0 0 0 0 -0 0</acceleration>
          <wrench>0 0 0 0 -0 0</wrench>
        </link>
      </model>
      <model name='unit_box_6'>
        <pose>17 -3 0.5 -0 -0 -0</pose>
        <link name='link'>
          <pose>17 -3 0.5 -0 -0 -0</pose>
          <velocity>0 0 0 0 -0 0</velocity>
          <acceleration>0 0 0 0 -0 0</acceleration>
          <wrench>0 0 0 0 -0 0</wrench>
        </link>
      </model>
      <model name='unit_box_7'>
        <pose>20 5 0.5 0 -0 0</pose>
        <link name='link'>
          <pose>20 5 0.5 0 -0 0</pose>
          <velocity>0 0 0 0 -0 0</velocity>
          <acceleration>0 0 0 0 -0 0</acceleration>
          <wrench>0 0 0 0 -0 0</wrench>
        </link>
      </model>
      <model name='unit_box_8'>
        <pose>21 -3 0.5 -0 -0 -0</pose>
        <link name='link'>
          <pose>21 -3 0.5 -0 -0 -0</pose>
          <velocity>0 0 0 0 -0 0</velocity>
          <acceleration>0 0 0 0 -0 0</acceleration>
          <wrench>0 0 0 0 -0 0</wrench>
        </link>
      </model>
      <model name='unit_box_9'>
        <pose>3.46096 -2.45532 0.5 0 -0 0</pose>
        <link name='link'>
          <pose>3.46096 -2.45532 0.5 0 -0 0</pose>
          <velocity>0 0 0 0 -0 0</velocity>
          <acceleration>0 0 0 0 -0 0</acceleration>
          <wrench>0 0 0 0 -0 0</wrench>
        </link>
      </model>
      <model name='unit_sphere_2'>
        <pose>-31.4187 -0.544868 0.5 0 -0 0</pose>
        <link name='link'>
          <pose>-31.4187 -0.544868 0.5 0 -0 0</pose>
          <velocity>0 0 0 0 -0 0</velocity>
          <acceleration>0 0 0 0 -0 0</acceleration>
          <wrench>0 0 0 0 -0 0</wrench>
        </link>
      </model>
    </state>
    <model name='unit_sphere_2'>
      <pose>-31.4187 -0.544868 0.5 0 -0 0</pose>
      <link name='link'>
        <inertial>
          <mass>1</mass>
          <inertia>
            <ixx>1</ixx>
            <ixy>0</ixy>
            <ixz>0</ixz>
            <iyy>1</iyy>
            <iyz>0</iyz>
            <izz>1</izz>
          </inertia>
        </inertial>
        <collision name='collision'>
          <geometry>
            <sphere>
              <radius>0.5</radius>
            </sphere>
          </geometry>
          <max_contacts>10</max_contacts>
          <surface>
            <bounce/>
            <friction>
              <ode/>
            </friction>
            <contact>
              <ode/>
            </contact>
          </surface>
        </collision>
        <visual name='visual'>
          <geometry>
            <sphere>
              <radius>0.5</radius>
            </sphere>
          </geometry>
          <material>
            <script>
              <uri>file://media/materials/scripts/gazebo.material</uri>
              <name>Gazebo/Grey</name>
            </script>
          </material>
        </visual>
        <velocity_decay>
          <linear>0</linear>
          <angular>0</angular>
        </velocity_decay>
        <self_collide>0</self_collide>
        <kinematic>0</kinematic>
        <gravity>1</gravity>
      </link>
      <static>0</static>
    </model>
    <model name='unit_box_1'>
      <pose>8.4453 -3 0.5 0 -0 0</pose>
      <link name='link'>
        <inertial>
          <mass>1</mass>
          <inertia>
            <ixx>1</ixx>
            <ixy>0</ixy>
            <ixz>0</ixz>
            <iyy>1</iyy>
            <iyz>0</iyz>
            <izz>1</izz>
          </inertia>
        </inertial>
        <collision name='collision'>
          <geometry>
            <box>
              <size>1 1 1</size>
            </box>
          </geometry>
          <max_contacts>10</max_contacts>
          <surface>
            <bounce/>
            <friction>
              <ode/>
            </friction>
            <contact>
              <ode/>
            </contact>
          </surface>
        </collision>
        <visual name='visual'>
          <geometry>
            <box>
              <size>1 1 1</size>
            </box>
          </geometry>
          <material>
            <script>
              <uri>file://media/materials/scripts/gazebo.material</uri>
              <name>Gazebo/Grey</name>
            </script>
          </material>
        </visual>
        <velocity_decay>
          <linear>0</linear>
          <angular>0</angular>
        </velocity_decay>
        <self_collide>0</self_collide>
        <kinematic>0</kinematic>
        <gravity>1</gravity>
      </link>
      <static>0</static>
    </model>
    <model name='unit_box_2'>
      <pose>14 -4 0.5 0 -0 0</pose>
      <link name='link'>
        <inertial>
          <mass>1</mass>
          <inertia>
            <ixx>1</ixx>
            <ixy>0</ixy>
            <ixz>0</ixz>
            <iyy>1</iyy>
            <iyz>0</iyz>
            <izz>1</izz>
          </inertia>
        </inertial>
        <collision name='collision'>
          <geometry>
            <box>
              <size>1 1 1</size>
            </box>
          </geometry>
          <max_contacts>10</max_contacts>
          <surface>
            <bounce/>
            <friction>
              <ode/>
            </friction>
            <contact>
              <ode/>
            </contact>
          </surface>
        </collision>
        <visual name='visual'>
          <geometry>
            <box>
              <size>1 1 1</size>
            </box>
          </geometry>
          <material>
            <script>
              <uri>file://media/materials/scripts/gazebo.material</uri>
              <name>Gazebo/Grey</name>
            </script>
          </material>
        </visual>
        <velocity_decay>
          <linear>0</linear>
          <angular>0</angular>
        </velocity_decay>
        <self_collide>0</self_collide>
        <kinematic>0</kinematic>
        <gravity>1</gravity>
      </link>
      <static>0</static>
    </model>
    <model name='unit_box_3'>
      <pose>7 3 0.5 0 -0 0</pose>
      <link name='link'>
        <inertial>
          <mass>1</mass>
          <inertia>
            <ixx>1</ixx>
            <ixy>0</ixy>
            <ixz>0</ixz>
            <iyy>1</iyy>
            <iyz>0</iyz>
            <izz>1</izz>
          </inertia>
        </inertial>
        <collision name='collision'>
          <geometry>
            <box>
              <size>1 1 1</size>
            </box>
          </geometry>
          <max_contacts>10</max_contacts>
          <surface>
            <bounce/>
            <friction>
              <ode/>
            </friction>
            <contact>
              <ode/>
            </contact>
          </surface>
        </collision>
        <visual name='visual'>
          <geometry>
            <box>
              <size>1 1 1</size>
            </box>
          </geometry>
          <material>
            <script>
              <uri>file://media/materials/scripts/gazebo.material</uri>
              <name>Gazebo/Grey</name>
            </script>
          </material>
        </visual>
        <velocity_decay>
          <linear>0</linear>
          <angular>0</angular>
        </velocity_decay>
        <self_collide>0</self_collide>
        <kinematic>0</kinematic>
        <gravity>1</gravity>
      </link>
      <static>0</static>
    </model>
    <model name='unit_box_4'>
      <pose>12 2.5989 0.5 0 -0 0</pose>
      <link name='link'>
        <inertial>
          <mass>1</mass>
          <inertia>
            <ixx>1</ixx>
            <ixy>0</ixy>
            <ixz>0</ixz>
            <iyy>1</iyy>
            <iyz>0</iyz>
            <izz>1</izz>
          </inertia>
        </inertial>
        <collision name='collision'>
          <geometry>
            <box>
              <size>1 1 1</size>
            </box>
          </geometry>
          <max_contacts>10</max_contacts>
          <surface>
            <bounce/>
            <friction>
              <ode/>
            </friction>
            <contact>
              <ode/>
            </contact>
          </surface>
        </collision>
        <visual name='visual'>
          <geometry>
            <box>
              <size>1 1 1</size>
            </box>
          </geometry>
          <material>
            <script>
              <uri>file://media/materials/scripts/gazebo.material</uri>
              <name>Gazebo/Grey</name>
            </script>
          </material>
        </visual>
        <velocity_decay>
          <linear>0</linear>
          <angular>0</angular>
        </velocity_decay>
        <self_collide>0</self_collide>
        <kinematic>0</kinematic>
        <gravity>1</gravity>
      </link>
      <static>0</static>
    </model>
    <model name='unit_box_5'>
      <pose>4 3.45674 0.5 0 -0 0</pose>
      <link name='link'>
        <inertial>
          <mass>1</mass>
          <inertia>
            <ixx>1</ixx>
            <ixy>0</ixy>
            <ixz>0</ixz>
            <iyy>1</iyy>
            <iyz>0</iyz>
            <izz>1</izz>
          </inertia>
        </inertial>
        <collision name='collision'>
          <geometry>
            <box>
              <size>1 1 1</size>
            </box>
          </geometry>
          <max_contacts>10</max_contacts>
          <surface>
            <bounce/>
            <friction>
              <ode/>
            </friction>
            <contact>
              <ode/>
            </contact>
          </surface>
        </collision>
        <visual name='visual'>
          <geometry>
            <box>
              <size>1 1 1</size>
            </box>
          </geometry>
          <material>
            <script>
              <uri>file://media/materials/scripts/gazebo.material</uri>
              <name>Gazebo/Grey</name>
            </script>
          </material>
        </visual>
        <velocity_decay>
          <linear>0</linear>
          <angular>0</angular>
        </velocity_decay>
        <self_collide>0</self_collide>
        <kinematic>0</kinematic>
        <gravity>1</gravity>
      </link>
      <static>0</static>
    </model>
    <model name='unit_box_6'>
      <pose>17 -3 0.5 0 -0 0</pose>
      <link name='link'>
        <inertial>
          <mass>1</mass>
          <inertia>
            <ixx>1</ixx>
            <ixy>0</ixy>
            <ixz>0</ixz>
            <iyy>1</iyy>
            <iyz>0</iyz>
            <izz>1</izz>
          </inertia>
        </inertial>
        <collision name='collision'>
          <geometry>
            <box>
              <size>1 1 1</size>
            </box>
          </geometry>
          <max_contacts>10</max_contacts>
          <surface>
            <bounce/>
            <friction>
              <ode/>
            </friction>
            <contact>
              <ode/>
            </contact>
          </surface>
        </collision>
        <visual name='visual'>
          <geometry>
            <box>
              <size>1 1 1</size>
            </box>
          </geometry>
          <material>
            <script>
              <uri>file://media/materials/scripts/gazebo.material</uri>
              <name>Gazebo/Grey</name>
            </script>
          </material>
        </visual>
        <velocity_decay>
          <linear>0</linear>
          <angular>0</angular>
        </velocity_decay>
        <self_collide>0</self_collide>
        <kinematic>0</kinematic>
        <gravity>1</gravity>
      </link>
      <static>0</static>
    </model>
    <model name='unit_box_7'>
      <pose>20 5 0.5 0 -0 0</pose>
      <link name='link'>
        <inertial>
          <mass>1</mass>
          <inertia>
            <ixx>1</ixx>
            <ixy>0</ixy>
            <ixz>0</ixz>
            <iyy>1</iyy>
            <iyz>0</iyz>
            <izz>1</izz>
          </inertia>
        </inertial>
        <collision name='collision'>
          <geometry>
            <box>
              <size>1 1 1</size>
            </box>
          </geometry>
          <max_contacts>10</max_contacts>
          <surface>
            <bounce/>
            <friction>
              <ode/>
            </friction>
            <contact>
              <ode/>
            </contact>
          </surface>
        </collision>
        <visual name='visual'>
          <geometry>
            <box>
              <size>1 1 1</size>
            </box>
          </geometry>
          <material>
            <script>
              <uri>file://media/materials/scripts/gazebo.material</uri>
              <name>Gazebo/Grey</name>
            </script>
          </material>
        </visual>
        <velocity_decay>
          <linear>0</linear>
          <angular>0</angular>
        </velocity_decay>
        <self_collide>0</self_collide>
        <kinematic>0</kinematic>
        <gravity>1</gravity>
      </link>
      <static>0</static>
    </model>
    <model name='unit_box_8'>
      <pose>21 -3 0.5 0 -0 0</pose>
      <link name='link'>
        <inertial>
          <mass>1</mass>
          <inertia>
            <ixx>1</ixx>
            <ixy>0</ixy>
            <ixz>0</ixz>
            <iyy>1</iyy>
            <iyz>0</iyz>
            <izz>1</izz>
          </inertia>
        </inertial>
        <collision name='collision'>
          <geometry>
            <box>
              <size>1 1 1</size>
            </box>
          </geometry>
          <max_contacts>10</max_contacts>
          <surface>
            <bounce/>
            <friction>
              <ode/>
            </friction>
            <contact>
              <ode/>
            </contact>
          </surface>
        </collision>
        <visual name='visual'>
          <geometry>
            <box>
              <size>1 1 1</size>
            </box>
          </geometry>
          <material>
            <script>
              <uri>file://media/materials/scripts/gazebo.material</uri>
              <name>Gazebo/Grey</name>
            </script>
          </material>
        </visual>
        <velocity_decay>
          <linear>0</linear>
          <angular>0</angular>
        </velocity_decay>
        <self_collide>0</self_collide>
        <kinematic>0</kinematic>
        <gravity>1</gravity>
      </link>
      <static>0</static>
    </model>
    <model name='unit_box_9'>
      <pose>3.46096 -2.45532 0.5 0 -0 0</pose>
      <link name='link'>
        <inertial>
          <mass>1</mass>
          <inertia>
            <ixx>1</ixx>
            <ixy>0</ixy>
            <ixz>0</ixz>
            <iyy>1</iyy>
            <iyz>0</iyz>
            <izz>1</izz>
          </inertia>
        </inertial>
        <collision name='collision'>
          <geometry>
            <box>
              <size>1 1 1</size>
            </box>
          </geometry>
          <max_contacts>10</max_contacts>
          <surface>
            <bounce/>
            <friction>
              <ode/>
            </friction>
            <contact>
              <ode/>
            </contact>
          </surface>
        </collision>
        <visual name='visual'>
          <geometry>
            <box>
              <size>1 1 1</size>
            </box>
          </geometry>
          <material>
            <script>
              <uri>file://media/materials/scripts/gazebo.material</uri>
              <name>Gazebo/Grey</name>
            </script>
          </material>
        </visual>
        <velocity_decay>
          <linear>0</linear>
          <angular>0</angular>
        </velocity_decay>
        <self_collide>0</self_collide>
        <kinematic>0</kinematic>
        <gravity>1</gravity>
      </link>
      <static>0</static>
    </model>
    <model name='unit_box_10'>
      <pose>25 3 0.5 0 -0 0</pose>
      <link name='link'>
        <inertial>
          <mass>1</mass>
          <inertia>
            <ixx>1</ixx>
            <ixy>0</ixy>
            <ixz>0</ixz>
            <iyy>1</iyy>
            <iyz>0</iyz>
            <izz>1</izz>
          </inertia>
        </inertial>
        <collision name='collision'>
          <geometry>
            <box>
              <size>1 1 1</size>
            </box>
          </geometry>
          <max_contacts>10</max_contacts>
          <surface>
            <bounce/>
            <friction>
              <ode/>
            </friction>
            <contact>
              <ode/>
            </contact>
          </surface>
        </collision>
        <visual name='visual'>
          <geometry>
            <box>
              <size>1 1 1</size>
            </box>
          </geometry>
          <material>
            <script>
              <uri>file://media/materials/scripts/gazebo.material</uri>
              <name>Gazebo/Grey</name>
            </script>
          </material>
        </visual>
        <velocity_decay>
          <linear>0</linear>
          <angular>0</angular>
        </velocity_decay>
        <self_collide>0</self_collide>
        <kinematic>0</kinematic>
        <gravity>1</gravity>
      </link>
      <static>0</static>
    </model>
    <model name='catvehicle'>
      <link name='base_link'>
        <pose>0 0 0 0 -0 0</pose>
        <inertial>
          <pose>4.39024e-09 0 1.0639 0 -0 0</pose>
          <mass>2050</mass>
          <inertia>
            <ixx>63.0001</ixx>
            <ixy>0</ixy>
            <ixz>-31</ixz>
            <iyy>1048</iyy>
            <iyz>0</iyz>
            <izz>1111</izz>
          </inertia>
        </inertial>
        <collision name='base_link_collision'>
          <pose>0 0 1.0639 0 -0 0</pose>
          <geometry>
            <box>
              <size>2.62 1.301 1.4478</size>
            </box>
          </geometry>
          <max_contacts>10</max_contacts>
          <surface>
            <bounce/>
            <friction>
              <ode/>
            </friction>
            <contact>
              <ode/>
            </contact>
          </surface>
        </collision>
        <collision name='base_link_collision_camera_left_link'>
          <pose>-0.75 0.6505 2.025 0 -0 1.5708</pose>
          <geometry>
            <box>
              <size>0.1 0.1 0.1</size>
            </box>
          </geometry>
          <surface>
            <contact>
              <ode/>
            </contact>
            <friction>
              <ode>
                <mu>0.6</mu>
                <mu2>0.5</mu2>
              </ode>
            </friction>
            <bounce/>
          </surface>
          <surface>
            <contact>
              <ode/>
            </contact>
            <friction>
              <ode/>
            </friction>
          </surface>
          <max_contacts>10</max_contacts>
        </collision>
        <collision name='base_link_collision_camera_link'>
          <pose>0 0 2.1 0 -0 0</pose>
          <geometry>
            <box>
              <size>0.25 0.25 0.25</size>
            </box>
          </geometry>
          <max_contacts>10</max_contacts>
          <surface>
            <bounce/>
            <friction>
              <ode/>
            </friction>
            <contact>
              <ode/>
            </contact>
          </surface>
        </collision>
        <collision name='base_link_collision_camera_right_link'>
          <pose>-0.75 -0.6505 2.025 0 0 -1.5708</pose>
          <geometry>
            <box>
              <size>0.1 0.1 0.1</size>
            </box>
          </geometry>
          <surface>
            <contact>
              <ode/>
            </contact>
            <friction>
              <ode>
                <mu>0.6</mu>
                <mu2>0.5</mu2>
              </ode>
            </friction>
            <bounce/>
          </surface>
          <surface>
            <contact>
              <ode/>
            </contact>
            <friction>
              <ode/>
            </friction>
          </surface>
          <max_contacts>10</max_contacts>
        </collision>
        <collision name='base_link_collision_front_laser_link'>
          <pose>2.4 0 0.8589 0 -0 0</pose>
          <geometry>
            <box>
              <size>0.25 0.25 0.25</size>
            </box>
          </geometry>
          <surface>
            <contact>
              <ode/>
            </contact>
            <friction>
              <ode>
                <mu>0.6</mu>
                <mu2>0.5</mu2>
              </ode>
            </friction>
            <bounce/>
          </surface>
          <surface>
            <contact>
              <ode/>
            </contact>
            <friction>
              <ode/>
            </friction>
          </surface>
          <max_contacts>10</max_contacts>
        </collision>
        <collision name='base_link_collision_velodyne_link'>
          <pose>0 0 2.235 0 -0 0</pose>
          <geometry>
            <box>
              <size>0.25 0.25 0.25</size>
            </box>
          </geometry>
          <surface>
            <contact>
              <ode/>
            </contact>
            <friction>
              <ode>
                <mu>0.6</mu>
                <mu2>0.5</mu2>
              </ode>
            </friction>
            <bounce/>
          </surface>
          <surface>
            <contact>
              <ode/>
            </contact>
            <friction>
              <ode/>
            </friction>
          </surface>
          <max_contacts>10</max_contacts>
        </collision>
        <visual name='base_link_visual'>
          <pose>-0.25 0 1.1139 0 -0 0</pose>
          <geometry>
            <mesh>
              <scale>1 1 1</scale>
              <uri>/home/ece446/cvchallenge_task3_ws/src/catvehicle/meshes/ford_escape_no_wheels_2.dae</uri>
            </mesh>
          </geometry>
        </visual>
        <visual name='base_link_visual_camera_left_link'>
          <pose>-0.75 0.6505 2.025 0 -0 1.5708</pose>
          <geometry>
            <box>
              <size>0.1 0.1 0.1</size>
            </box>
          </geometry>
        </visual>
        <visual name='base_link_visual_camera_link'>
          <pose>0 0 2.1 0 -0 0</pose>
          <geometry>
            <box>
              <size>0.25 0.25 0.25</size>
            </box>
          </geometry>
        </visual>
        <visual name='base_link_visual_camera_right_link'>
          <pose>-0.75 -0.6505 2.025 0 0 -1.5708</pose>
          <geometry>
            <box>
              <size>0.1 0.1 0.1</size>
            </box>
          </geometry>
        </visual>
        <visual name='base_link_visual_front_laser_link'>
          <pose>2.4 0 0.8589 0 -0 0</pose>
          <geometry>
            <box>
              <size>0.25 0.25 0.25</size>
            </box>
          </geometry>
        </visual>
        <visual name='base_link_visual_velodyne_link'>
          <pose>0 0 2.235 0 -0 0</pose>
          <geometry>
            <mesh>
              <scale>1 1 1</scale>
              <uri>/home/ece446/cvchallenge_task3_ws/src/catvehicle/meshes/hokuyo.dae</uri>
            </mesh>
          </geometry>
        </visual>
        <velocity_decay>
          <linear>0</linear>
          <angular>0</angular>
        </velocity_decay>
        <velocity_decay>
          <linear>0</linear>
          <angular>0</angular>
        </velocity_decay>
        <sensor name='lidar_sensor' type='ray'>
          <visualize>0</visualize>
          <update_rate>5</update_rate>
          <ray>
            <scan>
              <horizontal>
                <samples>100</samples>
                <resolution>1</resolution>
                <min_angle>-0.4</min_angle>
                <max_angle>0.4</max_angle>
              </horizontal>
              <vertical>
                <samples>20</samples>
                <resolution>1</resolution>
                <min_angle>-0.0349066</min_angle>
                <max_angle>0.326</max_angle>
              </vertical>
            </scan>
            <range>
              <min>1</min>
              <max>50</max>
              <resolution>0.02</resolution>
            </range>
          </ray>
          <plugin name='laser_controller' filename='libgazebo_ros_block_laser.so'>
            <frameName>velodyne_link</frameName>
            <hokuyoMinIntensity>101</hokuyoMinIntensity>
            <robotNamespace>/catvehicle</robotNamespace>
            <topicName>lidar_points</topicName>
            <gaussianNoise>0.02</gaussianNoise>
            <updateRate>5</updateRate>
          </plugin>
          <pose>0 0 2.235 0 -0 0</pose>
        </sensor>
        <velocity_decay>
          <linear>0</linear>
          <angular>0</angular>
        </velocity_decay>
        <velocity_decay>
          <linear>0</linear>
          <angular>0</angular>
        </velocity_decay>
        <sensor name='camera_left' type='camera'>
          <update_rate>30</update_rate>
          <camera name='left'>
            <horizontal_fov>1.39626</horizontal_fov>
            <image>
              <width>800</width>
              <height>800</height>
              <format>R8G8B8</format>
            </image>
            <clip>
              <near>0.02</near>
              <far>300</far>
            </clip>
            <noise>
              <type>gaussian</type>
              <mean>0</mean>
              <stddev>0.007</stddev>
            </noise>
          </camera>
          <plugin name='camera_left_controller' filename='libgazebo_ros_camera.so'>
            <alwaysOn>true</alwaysOn>
            <updateRate>0.0</updateRate>
            <robotNamespace>/catvehicle</robotNamespace>
            <cameraName>camera_left</cameraName>
            <imageTopicName>image_raw_left</imageTopicName>
            <cameraInfoTopicName>camera_left_info</cameraInfoTopicName>
            <frameName>camera_left_link</frameName>
            <hackBaseline>0.07</hackBaseline>
            <distortionK1>0.0</distortionK1>
            <distortionK2>0.0</distortionK2>
            <distortionK3>0.0</distortionK3>
            <distortionT1>0.0</distortionT1>
            <distortionT2>0.0</distortionT2>
          </plugin>
          <pose>-0.75 0.6505 2.025 0 -0 1.5708</pose>
        </sensor>
        <velocity_decay>
          <linear>0</linear>
          <angular>0</angular>
        </velocity_decay>
        <velocity_decay>
          <linear>0</linear>
          <angular>0</angular>
        </velocity_decay>
        <sensor name='camera_right' type='camera'>
          <update_rate>30</update_rate>
          <camera name='right'>
            <horizontal_fov>1.39626</horizontal_fov>
            <image>
              <width>800</width>
              <height>800</height>
              <format>R8G8B8</format>
            </image>
            <clip>
              <near>0.02</near>
              <far>300</far>
            </clip>
            <noise>
              <type>gaussian</type>
              <mean>0</mean>
              <stddev>0.007</stddev>
            </noise>
          </camera>
          <plugin name='camera_right_controller' filename='libgazebo_ros_camera.so'>
            <alwaysOn>true</alwaysOn>
            <updateRate>0.0</updateRate>
            <robotNamespace>/catvehicle</robotNamespace>
            <cameraName>camera_right</cameraName>
            <imageTopicName>image_raw_right</imageTopicName>
            <cameraInfoTopicName>camera_right_info</cameraInfoTopicName>
            <frameName>camera_right_link</frameName>
            <hackBaseline>0.07</hackBaseline>
            <distortionK1>0.0</distortionK1>
            <distortionK2>0.0</distortionK2>
            <distortionK3>0.0</distortionK3>
            <distortionT1>0.0</distortionT1>
            <distortionT2>0.0</distortionT2>
          </plugin>
          <pose>-0.75 -0.6505 2.025 0 0 -1.5708</pose>
        </sensor>
        <velocity_decay>
          <linear>0</linear>
          <angular>0</angular>
        </velocity_decay>
        <gravity>1</gravity>
        <velocity_decay>
          <linear>0</linear>
          <angular>0</angular>
        </velocity_decay>
        <self_collide>0</self_collide>
        <sensor name='sick_lms291' type='ray'>
          <visualize>1</visualize>
          <update_rate>50</update_rate>
          <ray>
            <scan>
              <horizontal>
                <samples>180</samples>
                <resolution>1</resolution>
                <min_angle>-1.57</min_angle>
                <max_angle>1.57</max_angle>
              </horizontal>
            </scan>
            <range>
              <min>1.5</min>
              <max>80</max>
              <resolution>0.05</resolution>
            </range>
          </ray>
          <plugin name='sick_lms291_controller' filename='libgazebo_ros_laser.so'>
            <topicName>/catvehicle/front_laser_points</topicName>
            <frameName>front_laser_link</frameName>
            <gaussianNoise>0.02</gaussianNoise>
            <robotNamespace>/catvehicle/</robotNamespace>
          </plugin>
          <pose>2.4 0 0.8589 0 -0 0</pose>
        </sensor>
        <kinematic>0</kinematic>
      </link>
      <link name='back_left_wheel_link'>
        <pose>-1.31 0.765 0.66 0 -0 0</pose>
        <inertial>
          <pose>0 0 0 0 -0 0</pose>
          <mass>40</mass>
          <inertia>
            <ixx>54</ixx>
            <ixy>0</ixy>
            <ixz>0</ixz>
            <iyy>56</iyy>
            <iyz>0</iyz>
            <izz>104</izz>
          </inertia>
        </inertial>
        <collision name='back_left_wheel_link_collision'>
          <pose>0 0 0 1.5708 -0 0</pose>
          <geometry>
            <cylinder>
              <length>0.229</length>
              <radius>0.356</radius>
            </cylinder>
          </geometry>
          <surface>
            <contact>
              <ode>
                <kp>1e+07</kp>
                <kd>1</kd>
                <max_vel>10</max_vel>
                <min_depth>0.01</min_depth>
              </ode>
            </contact>
            <friction>
              <ode>
                <mu>10000</mu>
                <mu2>10000</mu2>
              </ode>
            </friction>
            <bounce/>
          </surface>
          <max_contacts>10</max_contacts>
        </collision>
        <visual name='back_left_wheel_link_visual'>
          <pose>0 0 0 0 -0 1.5708</pose>
          <geometry>
            <mesh>
              <scale>1 1 1</scale>
              <uri>/home/ece446/cvchallenge_task3_ws/src/catvehicle/meshes/ford_escape_wheel.dae</uri>
            </mesh>
          </geometry>
        </visual>
        <gravity>1</gravity>
        <velocity_decay>
          <linear>0</linear>
          <angular>0</angular>
        </velocity_decay>
        <self_collide>0</self_collide>
        <kinematic>0</kinematic>
      </link>
      <joint name='back_left_wheel_joint' type='revolute'>
        <child>back_left_wheel_link</child>
        <parent>base_link</parent>
        <axis>
          <xyz>0 1 0</xyz>
          <limit>
            <lower>-1e+16</lower>
            <upper>1e+16</upper>
          </limit>
          <dynamics>
            <damping>0.1</damping>
          </dynamics>
        </axis>
      </joint>
      <link name='back_right_wheel_link'>
        <pose>-1.31 -0.765 0.66 0 -0 0</pose>
        <inertial>
          <pose>0 0 0 0 -0 0</pose>
          <mass>40</mass>
          <inertia>
            <ixx>54</ixx>
            <ixy>0</ixy>
            <ixz>0</ixz>
            <iyy>56</iyy>
            <iyz>0</iyz>
            <izz>104</izz>
          </inertia>
        </inertial>
        <collision name='back_right_wheel_link_collision'>
          <pose>0 0 0 1.5708 -0 0</pose>
          <geometry>
            <cylinder>
              <length>0.229</length>
              <radius>0.356</radius>
            </cylinder>
          </geometry>
          <surface>
            <contact>
              <ode>
                <kp>1e+07</kp>
                <kd>1</kd>
                <max_vel>10</max_vel>
                <min_depth>0.01</min_depth>
              </ode>
            </contact>
            <friction>
              <ode>
                <mu>10000</mu>
                <mu2>10000</mu2>
              </ode>
            </friction>
            <bounce/>
          </surface>
          <max_contacts>10</max_contacts>
        </collision>
        <visual name='back_right_wheel_link_visual'>
          <pose>0 0 0 0 0 -1.5708</pose>
          <geometry>
            <mesh>
              <scale>1 1 1</scale>
              <uri>/home/ece446/cvchallenge_task3_ws/src/catvehicle/meshes/ford_escape_wheel.dae</uri>
            </mesh>
          </geometry>
        </visual>
        <gravity>1</gravity>
        <velocity_decay>
          <linear>0</linear>
          <angular>0</angular>
        </velocity_decay>
        <self_collide>0</self_collide>
        <kinematic>0</kinematic>
      </link>
      <joint name='back_right_wheel_joint' type='revolute'>
        <child>back_right_wheel_link</child>
        <parent>base_link</parent>
        <axis>
          <xyz>0 1 0</xyz>
          <limit>
            <lower>-1e+16</lower>
            <upper>1e+16</upper>
          </limit>
          <dynamics>
            <damping>0.1</damping>
          </dynamics>
        </axis>
      </joint>
      <link name='front_left_steering_link'>
        <pose>1.31 0.6555 0.66 0 -0 0</pose>
        <inertial>
          <pose>0 0 0 0 -0 0</pose>
          <mass>10</mass>
          <inertia>
            <ixx>0.4</ixx>
            <ixy>0</ixy>
            <ixz>0</ixz>
            <iyy>0.6</iyy>
            <iyz>0</iyz>
            <izz>0.4</izz>
          </inertia>
        </inertial>
        <collision name='front_left_steering_link_collision'>
          <pose>0 0 0 1.5708 -0 0</pose>
          <geometry>
            <cylinder>
              <length>0.01</length>
              <radius>0.1</radius>
            </cylinder>
          </geometry>
          <surface>
            <contact>
              <ode>
                <kp>1e+06</kp>
                <kd>0.1</kd>
                <max_vel>10</max_vel>
                <min_depth>0.01</min_depth>
              </ode>
            </contact>
            <friction>
              <ode>
                <mu>0.6</mu>
                <mu2>0.5</mu2>
              </ode>
            </friction>
            <bounce/>
          </surface>
          <max_contacts>10</max_contacts>
        </collision>
        <visual name='front_left_steering_link_visual'>
          <pose>0 0 0 1.5708 -0 0</pose>
          <geometry>
            <cylinder>
              <length>0.01</length>
              <radius>0.1</radius>
            </cylinder>
          </geometry>
        </visual>
        <gravity>1</gravity>
        <velocity_decay>
          <linear>0</linear>
          <angular>0</angular>
        </velocity_decay>
        <self_collide>0</self_collide>
        <kinematic>0</kinematic>
      </link>
      <joint name='front_left_steering_joint' type='revolute'>
        <child>front_left_steering_link</child>
        <parent>base_link</parent>
        <axis>
          <xyz>0 0 1</xyz>
          <limit>
            <lower>-0.6</lower>
            <upper>0.6</upper>
            <effort>1000</effort>
            <velocity>0.5</velocity>
          </limit>
          <dynamics/>
        </axis>
      </joint>
      <link name='front_left_wheel_link'>
        <pose>1.31 0.775 0.66 0 -0 0</pose>
        <inertial>
          <pose>0 0 0 0 -0 0</pose>
          <mass>40</mass>
          <inertia>
            <ixx>54</ixx>
            <ixy>0</ixy>
            <ixz>0</ixz>
            <iyy>56</iyy>
            <iyz>0</iyz>
            <izz>104</izz>
          </inertia>
        </inertial>
        <collision name='front_left_wheel_link_collision'>
          <pose>0 0 0 1.5708 -0 0</pose>
          <geometry>
            <cylinder>
              <length>0.229</length>
              <radius>0.356</radius>
            </cylinder>
          </geometry>
          <surface>
            <contact>
              <ode>
                <kp>1e+06</kp>
                <kd>1</kd>
                <max_vel>100</max_vel>
                <min_depth>0.01</min_depth>
              </ode>
            </contact>
            <friction>
              <ode>
                <mu>10000</mu>
                <mu2>10000</mu2>
              </ode>
            </friction>
            <bounce/>
          </surface>
          <max_contacts>10</max_contacts>
        </collision>
        <visual name='front_left_wheel_link_visual'>
          <pose>0 0 0 0 -0 1.5708</pose>
          <geometry>
            <mesh>
              <scale>1 1 1</scale>
              <uri>/home/ece446/cvchallenge_task3_ws/src/catvehicle/meshes/ford_escape_wheel.dae</uri>
            </mesh>
          </geometry>
        </visual>
        <gravity>1</gravity>
        <velocity_decay>
          <linear>0</linear>
          <angular>0</angular>
        </velocity_decay>
        <self_collide>0</self_collide>
        <kinematic>0</kinematic>
      </link>
      <joint name='front_left_wheel_joint' type='revolute'>
        <child>front_left_wheel_link</child>
        <parent>front_left_steering_link</parent>
        <axis>
          <xyz>0 1 0</xyz>
          <limit>
            <lower>-1e+16</lower>
            <upper>1e+16</upper>
          </limit>
          <dynamics>
            <damping>0.1</damping>
          </dynamics>
        </axis>
      </joint>
      <link name='front_right_steering_link'>
        <pose>1.31 -0.6555 0.66 0 -0 0</pose>
        <inertial>
          <pose>0 0 0 0 -0 0</pose>
          <mass>10</mass>
          <inertia>
            <ixx>0.4</ixx>
            <ixy>0</ixy>
            <ixz>0</ixz>
            <iyy>0.6</iyy>
            <iyz>0</iyz>
            <izz>0.4</izz>
          </inertia>
        </inertial>
        <collision name='front_right_steering_link_collision'>
          <pose>0 0 0 1.5708 -0 0</pose>
          <geometry>
            <cylinder>
              <length>0.01</length>
              <radius>0.1</radius>
            </cylinder>
          </geometry>
          <surface>
            <contact>
              <ode>
                <kp>1e+06</kp>
                <kd>0.1</kd>
                <max_vel>10</max_vel>
                <min_depth>0.01</min_depth>
              </ode>
            </contact>
            <friction>
              <ode>
                <mu>0.6</mu>
                <mu2>0.5</mu2>
              </ode>
            </friction>
            <bounce/>
          </surface>
          <max_contacts>10</max_contacts>
        </collision>
        <visual name='front_right_steering_link_visual'>
          <pose>0 0 0 1.5708 -0 0</pose>
          <geometry>
            <cylinder>
              <length>0.01</length>
              <radius>0.1</radius>
            </cylinder>
          </geometry>
        </visual>
        <gravity>1</gravity>
        <velocity_decay>
          <linear>0</linear>
          <angular>0</angular>
        </velocity_decay>
        <self_collide>0</self_collide>
        <kinematic>0</kinematic>
      </link>
      <joint name='front_right_steering_joint' type='revolute'>
        <child>front_right_steering_link</child>
        <parent>base_link</parent>
        <axis>
          <xyz>0 0 1</xyz>
          <limit>
            <lower>-0.6</lower>
            <upper>0.6</upper>
            <effort>1000</effort>
            <velocity>0.5</velocity>
          </limit>
          <dynamics/>
        </axis>
      </joint>
      <link name='front_right_wheel_link'>
        <pose>1.31 -0.775 0.66 0 -0 0</pose>
        <inertial>
          <pose>0 0 0 0 -0 0</pose>
          <mass>40</mass>
          <inertia>
            <ixx>54</ixx>
            <ixy>0</ixy>
            <ixz>0</ixz>
            <iyy>56</iyy>
            <iyz>0</iyz>
            <izz>104</izz>
          </inertia>
        </inertial>
        <collision name='front_right_wheel_link_collision'>
          <pose>0 0 0 1.5708 -0 0</pose>
          <geometry>
            <cylinder>
              <length>0.229</length>
              <radius>0.356</radius>
            </cylinder>
          </geometry>
          <surface>
            <contact>
              <ode>
                <kp>1e+06</kp>
                <kd>1</kd>
                <max_vel>100</max_vel>
                <min_depth>0.01</min_depth>
              </ode>
            </contact>
            <friction>
              <ode>
                <mu>10000</mu>
                <mu2>10000</mu2>
              </ode>
            </friction>
            <bounce/>
          </surface>
          <max_contacts>10</max_contacts>
        </collision>
        <visual name='front_right_wheel_link_visual'>
          <pose>0 0 0 0 0 -1.5708</pose>
          <geometry>
            <mesh>
              <scale>1 1 1</scale>
              <uri>/home/ece446/cvchallenge_task3_ws/src/catvehicle/meshes/ford_escape_wheel.dae</uri>
            </mesh>
          </geometry>
        </visual>
        <gravity>1</gravity>
        <velocity_decay>
          <linear>0</linear>
          <angular>0</angular>
        </velocity_decay>
        <self_collide>0</self_collide>
        <kinematic>0</kinematic>
      </link>
      <joint name='front_right_wheel_joint' type='revolute'>
        <child>front_right_wheel_link</child>
        <parent>front_right_steering_link</parent>
        <axis>
          <xyz>0 1 0</xyz>
          <limit>
            <lower>-1e+16</lower>
            <upper>1e+16</upper>
          </limit>
          <dynamics/>
        </axis>
      </joint>
      <plugin name='gazebo_ros_control' filename='libgazebo_ros_control.so'>
        <robotNamespace>/catvehicle</robotNamespace>
        <robotSimType>gazebo_ros_control/DefaultRobotHWSim</robotSimType>
      </plugin>
      <plugin name='joint_state_publisher' filename='libgazebo_ros_joint_state_publisher.so'>
        <jointName>back_left_wheel_joint, back_right_wheel_joint, front_left_steering_joint, front_right_steering_joint, front_right_wheel_joint, front_left_wheel_joint</jointName>
        <updateRate>50.0</updateRate>
        <robotNamespace>/catvehicle</robotNamespace>
        <alwaysOn>true</alwaysOn>
      </plugin>
      <static>0</static>
      <plugin name='cmdvel_controller' filename='libcatvehiclegazebo.so'>
        <robotNamespace>/catvehicle</robotNamespace>
      </plugin>
      <pose>0 0 0 0 -0 0</pose>
    </model>
    <model name='House 3'>
      <static>1</static>
      <link name='link'>
        <collision name='collision'>
          <geometry>
            <mesh>
              <uri>model://house_3/meshes/house_3.dae</uri>
            </mesh>
          </geometry>
          <max_contacts>10</max_contacts>
          <surface>
            <bounce/>
            <friction>
              <ode/>
            </friction>
            <contact>
              <ode/>
            </contact>
          </surface>
        </collision>
        <visual name='visual'>
          <geometry>
            <mesh>
              <uri>model://house_3/meshes/house_3.dae</uri>
            </mesh>
          </geometry>
          <material>
            <script>
              <uri>model://house_3/materials/scripts</uri>
              <uri>model://house_3/materials/textures</uri>
              <uri>model://house_1/materials/textures</uri>
              <name>House_3/Diffuse</name>
            </script>
            <shader type='normal_map_object_space'>
              <normal_map>model://house_1/materials/textures/House_1_Normal.png</normal_map>
            </shader>
          </material>
        </visual>
        <velocity_decay>
          <linear>0</linear>
          <angular>0</angular>
        </velocity_decay>
        <self_collide>0</self_collide>
        <kinematic>0</kinematic>
        <gravity>1</gravity>
      </link>
      <pose>15 -0.53632 0 0 -0 0</pose>
    </model>
  </world>
</sdf>
